<?xml version="1.0" encoding="UTF-8"?>
<testng-results ignored="0" total="20" passed="1" failed="19" skipped="0">
  <reporter-output>
  </reporter-output>
  <suite started-at="2024-01-18T01:15:36 PST" name="Suite" finished-at="2024-01-18T01:20:15 PST" duration-ms="278032">
    <groups>
    </groups>
    <test started-at="2024-01-18T01:15:36 PST" name="Test" finished-at="2024-01-18T01:20:15 PST" duration-ms="278032">
      <class name="com.kavi.demo.TestCases.DDD">
        <test-method is-config="true" signature="initializeExtentReprts()[pri:0, instance:com.kavi.demo.TestCases.DDD@1737834]" started-at="2024-01-18T01:15:36 PST" name="initializeExtentReprts" finished-at="2024-01-18T01:15:36 PST" duration-ms="698" status="PASS">
          <reporter-output>
          </reporter-output>
        </test-method> <!-- initializeExtentReprts -->
        <test-method is-config="true" signature="setUp(java.lang.String)[pri:0, instance:com.kavi.demo.TestCases.DDD@1737834]" started-at="2024-01-18T01:15:36 PST" name="setUp" finished-at="2024-01-18T01:15:49 PST" duration-ms="12235" status="PASS">
          <params>
            <param index="0">
              <value>
                <![CDATA[chrome]]>
              </value>
            </param>
          </params>
          <reporter-output>
          </reporter-output>
        </test-method> <!-- setUp -->
        <test-method is-config="true" signature="initializeReport(org.testng.ITestContext)[pri:0, instance:com.kavi.demo.TestCases.DDD@1737834]" started-at="2024-01-18T01:15:49 PST" name="initializeReport" finished-at="2024-01-18T01:15:49 PST" duration-ms="22" status="PASS">
          <params>
            <param index="0">
              <value>
                <![CDATA[org.testng.TestRunner@56082f59]]>
              </value>
            </param>
          </params>
          <reporter-output>
          </reporter-output>
        </test-method> <!-- initializeReport -->
        <test-method signature="DDDT()[pri:0, instance:com.kavi.demo.TestCases.DDD@1737834]" started-at="2024-01-18T01:15:49 PST" name="DDDT" finished-at="2024-01-18T01:16:03 PST" duration-ms="14140" status="FAIL">
          <exception class="java.lang.AssertionError">
            <message>
              <![CDATA[expected [https://qpot.omfysgroup.com/dashboard] but found [https://qpot.omfysgroup.com/]]]>
            </message>
            <full-stacktrace>
              <![CDATA[java.lang.AssertionError: expected [https://qpot.omfysgroup.com/dashboard] but found [https://qpot.omfysgroup.com/]
at org.testng.Assert.fail(Assert.java:110)
at org.testng.Assert.failNotEquals(Assert.java:1577)
at org.testng.Assert.assertEqualsImpl(Assert.java:149)
at org.testng.Assert.assertEquals(Assert.java:131)
at org.testng.Assert.assertEquals(Assert.java:655)
at org.testng.Assert.assertEquals(Assert.java:665)
at com.kavi.demo.TestCases.DDD.DDDT(DDD.java:56)
at java.base/jdk.internal.reflect.DirectMethodHandleAccessor.invoke(DirectMethodHandleAccessor.java:104)
at java.base/java.lang.reflect.Method.invoke(Method.java:578)
at org.testng.internal.invokers.MethodInvocationHelper.invokeMethod(MethodInvocationHelper.java:139)
at org.testng.internal.invokers.TestInvoker.invokeMethod(TestInvoker.java:677)
at org.testng.internal.invokers.TestInvoker.invokeTestMethod(TestInvoker.java:221)
at org.testng.internal.invokers.MethodRunner.runInSequence(MethodRunner.java:50)
at org.testng.internal.invokers.TestInvoker$MethodInvocationAgent.invoke(TestInvoker.java:969)
at org.testng.internal.invokers.TestInvoker.invokeTestMethods(TestInvoker.java:194)
at org.testng.internal.invokers.TestMethodWorker.invokeTestMethods(TestMethodWorker.java:148)
at org.testng.internal.invokers.TestMethodWorker.run(TestMethodWorker.java:128)
at java.base/java.util.ArrayList.forEach(ArrayList.java:1511)
at org.testng.TestRunner.privateRun(TestRunner.java:829)
at org.testng.TestRunner.run(TestRunner.java:602)
at org.testng.SuiteRunner.runTest(SuiteRunner.java:437)
at org.testng.SuiteRunner.runSequentially(SuiteRunner.java:431)
at org.testng.SuiteRunner.privateRun(SuiteRunner.java:391)
at org.testng.SuiteRunner.run(SuiteRunner.java:330)
at org.testng.SuiteRunnerWorker.runSuite(SuiteRunnerWorker.java:52)
at org.testng.SuiteRunnerWorker.run(SuiteRunnerWorker.java:95)
at org.testng.TestNG.runSuitesSequentially(TestNG.java:1256)
at org.testng.TestNG.runSuitesLocally(TestNG.java:1176)
at org.testng.TestNG.runSuites(TestNG.java:1099)
at org.testng.TestNG.run(TestNG.java:1067)
at org.testng.remote.AbstractRemoteTestNG.run(AbstractRemoteTestNG.java:115)
at org.testng.remote.RemoteTestNG.initAndRun(RemoteTestNG.java:251)
at org.testng.remote.RemoteTestNG.main(RemoteTestNG.java:77)
]]>
            </full-stacktrace>
          </exception> <!-- java.lang.AssertionError -->
          <reporter-output>
          </reporter-output>
        </test-method> <!-- DDDT -->
        <test-method is-config="true" signature="After_TC_Failure(java.lang.reflect.Method,org.testng.ITestResult)[pri:0, instance:com.kavi.demo.TestCases.DDD@1737834]" started-at="2024-01-18T01:16:03 PST" name="After_TC_Failure" finished-at="2024-01-18T01:16:03 PST" duration-ms="305" status="PASS">
          <params>
            <param index="0">
              <value>
                <![CDATA[public void com.kavi.demo.TestCases.DDD.DDDT() throws java.lang.Exception]]>
              </value>
            </param>
            <param index="1">
              <value>
                <![CDATA[[TestResult name=DDDT status=FAILURE method=DDD.DDDT()[pri:0, instance:com.kavi.demo.TestCases.DDD@1737834] output={null}]]]>
              </value>
            </param>
          </params>
          <reporter-output>
          </reporter-output>
        </test-method> <!-- After_TC_Failure -->
        <test-method is-config="true" signature="initializeReport(org.testng.ITestContext)[pri:0, instance:com.kavi.demo.TestCases.DDD@1737834]" started-at="2024-01-18T01:16:03 PST" name="initializeReport" finished-at="2024-01-18T01:16:03 PST" duration-ms="2" status="PASS">
          <params>
            <param index="0">
              <value>
                <![CDATA[org.testng.TestRunner@56082f59]]>
              </value>
            </param>
          </params>
          <reporter-output>
          </reporter-output>
        </test-method> <!-- initializeReport -->
        <test-method signature="DDDT()[pri:0, instance:com.kavi.demo.TestCases.DDD@1737834]" started-at="2024-01-18T01:16:03 PST" name="DDDT" finished-at="2024-01-18T01:16:17 PST" duration-ms="13565" status="FAIL">
          <exception class="java.lang.AssertionError">
            <message>
              <![CDATA[expected [https://qpot.omfysgroup.com/dashboard] but found [https://qpot.omfysgroup.com/]]]>
            </message>
            <full-stacktrace>
              <![CDATA[java.lang.AssertionError: expected [https://qpot.omfysgroup.com/dashboard] but found [https://qpot.omfysgroup.com/]
at org.testng.Assert.fail(Assert.java:110)
at org.testng.Assert.failNotEquals(Assert.java:1577)
at org.testng.Assert.assertEqualsImpl(Assert.java:149)
at org.testng.Assert.assertEquals(Assert.java:131)
at org.testng.Assert.assertEquals(Assert.java:655)
at org.testng.Assert.assertEquals(Assert.java:665)
at com.kavi.demo.TestCases.DDD.DDDT(DDD.java:56)
at java.base/jdk.internal.reflect.DirectMethodHandleAccessor.invoke(DirectMethodHandleAccessor.java:104)
at java.base/java.lang.reflect.Method.invoke(Method.java:578)
at org.testng.internal.invokers.MethodInvocationHelper.invokeMethod(MethodInvocationHelper.java:139)
at org.testng.internal.invokers.TestInvoker.invokeMethod(TestInvoker.java:677)
at org.testng.internal.invokers.TestInvoker.invokeTestMethod(TestInvoker.java:221)
at org.testng.internal.invokers.MethodRunner.runInSequence(MethodRunner.java:50)
at org.testng.internal.invokers.TestInvoker$MethodInvocationAgent.invoke(TestInvoker.java:969)
at org.testng.internal.invokers.TestInvoker.invokeTestMethods(TestInvoker.java:194)
at org.testng.internal.invokers.TestMethodWorker.invokeTestMethods(TestMethodWorker.java:148)
at org.testng.internal.invokers.TestMethodWorker.run(TestMethodWorker.java:128)
at java.base/java.util.ArrayList.forEach(ArrayList.java:1511)
at org.testng.TestRunner.privateRun(TestRunner.java:829)
at org.testng.TestRunner.run(TestRunner.java:602)
at org.testng.SuiteRunner.runTest(SuiteRunner.java:437)
at org.testng.SuiteRunner.runSequentially(SuiteRunner.java:431)
at org.testng.SuiteRunner.privateRun(SuiteRunner.java:391)
at org.testng.SuiteRunner.run(SuiteRunner.java:330)
at org.testng.SuiteRunnerWorker.runSuite(SuiteRunnerWorker.java:52)
at org.testng.SuiteRunnerWorker.run(SuiteRunnerWorker.java:95)
at org.testng.TestNG.runSuitesSequentially(TestNG.java:1256)
at org.testng.TestNG.runSuitesLocally(TestNG.java:1176)
at org.testng.TestNG.runSuites(TestNG.java:1099)
at org.testng.TestNG.run(TestNG.java:1067)
at org.testng.remote.AbstractRemoteTestNG.run(AbstractRemoteTestNG.java:115)
at org.testng.remote.RemoteTestNG.initAndRun(RemoteTestNG.java:251)
at org.testng.remote.RemoteTestNG.main(RemoteTestNG.java:77)
]]>
            </full-stacktrace>
          </exception> <!-- java.lang.AssertionError -->
          <reporter-output>
          </reporter-output>
        </test-method> <!-- DDDT -->
        <test-method is-config="true" signature="After_TC_Failure(java.lang.reflect.Method,org.testng.ITestResult)[pri:0, instance:com.kavi.demo.TestCases.DDD@1737834]" started-at="2024-01-18T01:16:17 PST" name="After_TC_Failure" finished-at="2024-01-18T01:16:17 PST" duration-ms="255" status="PASS">
          <params>
            <param index="0">
              <value>
                <![CDATA[public void com.kavi.demo.TestCases.DDD.DDDT() throws java.lang.Exception]]>
              </value>
            </param>
            <param index="1">
              <value>
                <![CDATA[[TestResult name=DDDT status=FAILURE method=DDD.DDDT()[pri:0, instance:com.kavi.demo.TestCases.DDD@1737834] output={null}]]]>
              </value>
            </param>
          </params>
          <reporter-output>
          </reporter-output>
        </test-method> <!-- After_TC_Failure -->
        <test-method is-config="true" signature="initializeReport(org.testng.ITestContext)[pri:0, instance:com.kavi.demo.TestCases.DDD@1737834]" started-at="2024-01-18T01:16:17 PST" name="initializeReport" finished-at="2024-01-18T01:16:17 PST" duration-ms="1" status="PASS">
          <params>
            <param index="0">
              <value>
                <![CDATA[org.testng.TestRunner@56082f59]]>
              </value>
            </param>
          </params>
          <reporter-output>
          </reporter-output>
        </test-method> <!-- initializeReport -->
        <test-method signature="DDDT()[pri:0, instance:com.kavi.demo.TestCases.DDD@1737834]" started-at="2024-01-18T01:16:17 PST" name="DDDT" finished-at="2024-01-18T01:16:31 PST" duration-ms="13521" status="FAIL">
          <exception class="java.lang.AssertionError">
            <message>
              <![CDATA[expected [https://qpot.omfysgroup.com/dashboard] but found [https://qpot.omfysgroup.com/]]]>
            </message>
            <full-stacktrace>
              <![CDATA[java.lang.AssertionError: expected [https://qpot.omfysgroup.com/dashboard] but found [https://qpot.omfysgroup.com/]
at org.testng.Assert.fail(Assert.java:110)
at org.testng.Assert.failNotEquals(Assert.java:1577)
at org.testng.Assert.assertEqualsImpl(Assert.java:149)
at org.testng.Assert.assertEquals(Assert.java:131)
at org.testng.Assert.assertEquals(Assert.java:655)
at org.testng.Assert.assertEquals(Assert.java:665)
at com.kavi.demo.TestCases.DDD.DDDT(DDD.java:56)
at java.base/jdk.internal.reflect.DirectMethodHandleAccessor.invoke(DirectMethodHandleAccessor.java:104)
at java.base/java.lang.reflect.Method.invoke(Method.java:578)
at org.testng.internal.invokers.MethodInvocationHelper.invokeMethod(MethodInvocationHelper.java:139)
at org.testng.internal.invokers.TestInvoker.invokeMethod(TestInvoker.java:677)
at org.testng.internal.invokers.TestInvoker.invokeTestMethod(TestInvoker.java:221)
at org.testng.internal.invokers.MethodRunner.runInSequence(MethodRunner.java:50)
at org.testng.internal.invokers.TestInvoker$MethodInvocationAgent.invoke(TestInvoker.java:969)
at org.testng.internal.invokers.TestInvoker.invokeTestMethods(TestInvoker.java:194)
at org.testng.internal.invokers.TestMethodWorker.invokeTestMethods(TestMethodWorker.java:148)
at org.testng.internal.invokers.TestMethodWorker.run(TestMethodWorker.java:128)
at java.base/java.util.ArrayList.forEach(ArrayList.java:1511)
at org.testng.TestRunner.privateRun(TestRunner.java:829)
at org.testng.TestRunner.run(TestRunner.java:602)
at org.testng.SuiteRunner.runTest(SuiteRunner.java:437)
at org.testng.SuiteRunner.runSequentially(SuiteRunner.java:431)
at org.testng.SuiteRunner.privateRun(SuiteRunner.java:391)
at org.testng.SuiteRunner.run(SuiteRunner.java:330)
at org.testng.SuiteRunnerWorker.runSuite(SuiteRunnerWorker.java:52)
at org.testng.SuiteRunnerWorker.run(SuiteRunnerWorker.java:95)
at org.testng.TestNG.runSuitesSequentially(TestNG.java:1256)
at org.testng.TestNG.runSuitesLocally(TestNG.java:1176)
at org.testng.TestNG.runSuites(TestNG.java:1099)
at org.testng.TestNG.run(TestNG.java:1067)
at org.testng.remote.AbstractRemoteTestNG.run(AbstractRemoteTestNG.java:115)
at org.testng.remote.RemoteTestNG.initAndRun(RemoteTestNG.java:251)
at org.testng.remote.RemoteTestNG.main(RemoteTestNG.java:77)
]]>
            </full-stacktrace>
          </exception> <!-- java.lang.AssertionError -->
          <reporter-output>
          </reporter-output>
        </test-method> <!-- DDDT -->
        <test-method is-config="true" signature="After_TC_Failure(java.lang.reflect.Method,org.testng.ITestResult)[pri:0, instance:com.kavi.demo.TestCases.DDD@1737834]" started-at="2024-01-18T01:16:31 PST" name="After_TC_Failure" finished-at="2024-01-18T01:16:31 PST" duration-ms="254" status="PASS">
          <params>
            <param index="0">
              <value>
                <![CDATA[public void com.kavi.demo.TestCases.DDD.DDDT() throws java.lang.Exception]]>
              </value>
            </param>
            <param index="1">
              <value>
                <![CDATA[[TestResult name=DDDT status=FAILURE method=DDD.DDDT()[pri:0, instance:com.kavi.demo.TestCases.DDD@1737834] output={null}]]]>
              </value>
            </param>
          </params>
          <reporter-output>
          </reporter-output>
        </test-method> <!-- After_TC_Failure -->
        <test-method is-config="true" signature="initializeReport(org.testng.ITestContext)[pri:0, instance:com.kavi.demo.TestCases.DDD@1737834]" started-at="2024-01-18T01:16:31 PST" name="initializeReport" finished-at="2024-01-18T01:16:31 PST" duration-ms="1" status="PASS">
          <params>
            <param index="0">
              <value>
                <![CDATA[org.testng.TestRunner@56082f59]]>
              </value>
            </param>
          </params>
          <reporter-output>
          </reporter-output>
        </test-method> <!-- initializeReport -->
        <test-method signature="DDDT()[pri:0, instance:com.kavi.demo.TestCases.DDD@1737834]" started-at="2024-01-18T01:16:31 PST" name="DDDT" finished-at="2024-01-18T01:16:44 PST" duration-ms="13364" status="FAIL">
          <exception class="java.lang.AssertionError">
            <message>
              <![CDATA[expected [https://qpot.omfysgroup.com/dashboard] but found [https://qpot.omfysgroup.com/]]]>
            </message>
            <full-stacktrace>
              <![CDATA[java.lang.AssertionError: expected [https://qpot.omfysgroup.com/dashboard] but found [https://qpot.omfysgroup.com/]
at org.testng.Assert.fail(Assert.java:110)
at org.testng.Assert.failNotEquals(Assert.java:1577)
at org.testng.Assert.assertEqualsImpl(Assert.java:149)
at org.testng.Assert.assertEquals(Assert.java:131)
at org.testng.Assert.assertEquals(Assert.java:655)
at org.testng.Assert.assertEquals(Assert.java:665)
at com.kavi.demo.TestCases.DDD.DDDT(DDD.java:91)
at java.base/jdk.internal.reflect.DirectMethodHandleAccessor.invoke(DirectMethodHandleAccessor.java:104)
at java.base/java.lang.reflect.Method.invoke(Method.java:578)
at org.testng.internal.invokers.MethodInvocationHelper.invokeMethod(MethodInvocationHelper.java:139)
at org.testng.internal.invokers.TestInvoker.invokeMethod(TestInvoker.java:677)
at org.testng.internal.invokers.TestInvoker.invokeTestMethod(TestInvoker.java:221)
at org.testng.internal.invokers.MethodRunner.runInSequence(MethodRunner.java:50)
at org.testng.internal.invokers.TestInvoker$MethodInvocationAgent.invoke(TestInvoker.java:969)
at org.testng.internal.invokers.TestInvoker.invokeTestMethods(TestInvoker.java:194)
at org.testng.internal.invokers.TestMethodWorker.invokeTestMethods(TestMethodWorker.java:148)
at org.testng.internal.invokers.TestMethodWorker.run(TestMethodWorker.java:128)
at java.base/java.util.ArrayList.forEach(ArrayList.java:1511)
at org.testng.TestRunner.privateRun(TestRunner.java:829)
at org.testng.TestRunner.run(TestRunner.java:602)
at org.testng.SuiteRunner.runTest(SuiteRunner.java:437)
at org.testng.SuiteRunner.runSequentially(SuiteRunner.java:431)
at org.testng.SuiteRunner.privateRun(SuiteRunner.java:391)
at org.testng.SuiteRunner.run(SuiteRunner.java:330)
at org.testng.SuiteRunnerWorker.runSuite(SuiteRunnerWorker.java:52)
at org.testng.SuiteRunnerWorker.run(SuiteRunnerWorker.java:95)
at org.testng.TestNG.runSuitesSequentially(TestNG.java:1256)
at org.testng.TestNG.runSuitesLocally(TestNG.java:1176)
at org.testng.TestNG.runSuites(TestNG.java:1099)
at org.testng.TestNG.run(TestNG.java:1067)
at org.testng.remote.AbstractRemoteTestNG.run(AbstractRemoteTestNG.java:115)
at org.testng.remote.RemoteTestNG.initAndRun(RemoteTestNG.java:251)
at org.testng.remote.RemoteTestNG.main(RemoteTestNG.java:77)
]]>
            </full-stacktrace>
          </exception> <!-- java.lang.AssertionError -->
          <reporter-output>
          </reporter-output>
        </test-method> <!-- DDDT -->
        <test-method is-config="true" signature="After_TC_Failure(java.lang.reflect.Method,org.testng.ITestResult)[pri:0, instance:com.kavi.demo.TestCases.DDD@1737834]" started-at="2024-01-18T01:16:44 PST" name="After_TC_Failure" finished-at="2024-01-18T01:16:44 PST" duration-ms="256" status="PASS">
          <params>
            <param index="0">
              <value>
                <![CDATA[public void com.kavi.demo.TestCases.DDD.DDDT() throws java.lang.Exception]]>
              </value>
            </param>
            <param index="1">
              <value>
                <![CDATA[[TestResult name=DDDT status=FAILURE method=DDD.DDDT()[pri:0, instance:com.kavi.demo.TestCases.DDD@1737834] output={null}]]]>
              </value>
            </param>
          </params>
          <reporter-output>
          </reporter-output>
        </test-method> <!-- After_TC_Failure -->
        <test-method is-config="true" signature="initializeReport(org.testng.ITestContext)[pri:0, instance:com.kavi.demo.TestCases.DDD@1737834]" started-at="2024-01-18T01:16:44 PST" name="initializeReport" finished-at="2024-01-18T01:16:44 PST" duration-ms="1" status="PASS">
          <params>
            <param index="0">
              <value>
                <![CDATA[org.testng.TestRunner@56082f59]]>
              </value>
            </param>
          </params>
          <reporter-output>
          </reporter-output>
        </test-method> <!-- initializeReport -->
        <test-method signature="DDDT()[pri:0, instance:com.kavi.demo.TestCases.DDD@1737834]" started-at="2024-01-18T01:16:44 PST" name="DDDT" finished-at="2024-01-18T01:16:58 PST" duration-ms="13453" status="FAIL">
          <exception class="java.lang.AssertionError">
            <message>
              <![CDATA[expected [https://qpot.omfysgroup.com/dashboard] but found [https://qpot.omfysgroup.com/]]]>
            </message>
            <full-stacktrace>
              <![CDATA[java.lang.AssertionError: expected [https://qpot.omfysgroup.com/dashboard] but found [https://qpot.omfysgroup.com/]
at org.testng.Assert.fail(Assert.java:110)
at org.testng.Assert.failNotEquals(Assert.java:1577)
at org.testng.Assert.assertEqualsImpl(Assert.java:149)
at org.testng.Assert.assertEquals(Assert.java:131)
at org.testng.Assert.assertEquals(Assert.java:655)
at org.testng.Assert.assertEquals(Assert.java:665)
at com.kavi.demo.TestCases.DDD.DDDT(DDD.java:56)
at java.base/jdk.internal.reflect.DirectMethodHandleAccessor.invoke(DirectMethodHandleAccessor.java:104)
at java.base/java.lang.reflect.Method.invoke(Method.java:578)
at org.testng.internal.invokers.MethodInvocationHelper.invokeMethod(MethodInvocationHelper.java:139)
at org.testng.internal.invokers.TestInvoker.invokeMethod(TestInvoker.java:677)
at org.testng.internal.invokers.TestInvoker.invokeTestMethod(TestInvoker.java:221)
at org.testng.internal.invokers.MethodRunner.runInSequence(MethodRunner.java:50)
at org.testng.internal.invokers.TestInvoker$MethodInvocationAgent.invoke(TestInvoker.java:969)
at org.testng.internal.invokers.TestInvoker.invokeTestMethods(TestInvoker.java:194)
at org.testng.internal.invokers.TestMethodWorker.invokeTestMethods(TestMethodWorker.java:148)
at org.testng.internal.invokers.TestMethodWorker.run(TestMethodWorker.java:128)
at java.base/java.util.ArrayList.forEach(ArrayList.java:1511)
at org.testng.TestRunner.privateRun(TestRunner.java:829)
at org.testng.TestRunner.run(TestRunner.java:602)
at org.testng.SuiteRunner.runTest(SuiteRunner.java:437)
at org.testng.SuiteRunner.runSequentially(SuiteRunner.java:431)
at org.testng.SuiteRunner.privateRun(SuiteRunner.java:391)
at org.testng.SuiteRunner.run(SuiteRunner.java:330)
at org.testng.SuiteRunnerWorker.runSuite(SuiteRunnerWorker.java:52)
at org.testng.SuiteRunnerWorker.run(SuiteRunnerWorker.java:95)
at org.testng.TestNG.runSuitesSequentially(TestNG.java:1256)
at org.testng.TestNG.runSuitesLocally(TestNG.java:1176)
at org.testng.TestNG.runSuites(TestNG.java:1099)
at org.testng.TestNG.run(TestNG.java:1067)
at org.testng.remote.AbstractRemoteTestNG.run(AbstractRemoteTestNG.java:115)
at org.testng.remote.RemoteTestNG.initAndRun(RemoteTestNG.java:251)
at org.testng.remote.RemoteTestNG.main(RemoteTestNG.java:77)
]]>
            </full-stacktrace>
          </exception> <!-- java.lang.AssertionError -->
          <reporter-output>
          </reporter-output>
        </test-method> <!-- DDDT -->
        <test-method is-config="true" signature="After_TC_Failure(java.lang.reflect.Method,org.testng.ITestResult)[pri:0, instance:com.kavi.demo.TestCases.DDD@1737834]" started-at="2024-01-18T01:16:58 PST" name="After_TC_Failure" finished-at="2024-01-18T01:16:58 PST" duration-ms="265" status="PASS">
          <params>
            <param index="0">
              <value>
                <![CDATA[public void com.kavi.demo.TestCases.DDD.DDDT() throws java.lang.Exception]]>
              </value>
            </param>
            <param index="1">
              <value>
                <![CDATA[[TestResult name=DDDT status=FAILURE method=DDD.DDDT()[pri:0, instance:com.kavi.demo.TestCases.DDD@1737834] output={null}]]]>
              </value>
            </param>
          </params>
          <reporter-output>
          </reporter-output>
        </test-method> <!-- After_TC_Failure -->
        <test-method is-config="true" signature="initializeReport(org.testng.ITestContext)[pri:0, instance:com.kavi.demo.TestCases.DDD@1737834]" started-at="2024-01-18T01:16:58 PST" name="initializeReport" finished-at="2024-01-18T01:16:58 PST" duration-ms="1" status="PASS">
          <params>
            <param index="0">
              <value>
                <![CDATA[org.testng.TestRunner@56082f59]]>
              </value>
            </param>
          </params>
          <reporter-output>
          </reporter-output>
        </test-method> <!-- initializeReport -->
        <test-method signature="DDDT()[pri:0, instance:com.kavi.demo.TestCases.DDD@1737834]" started-at="2024-01-18T01:16:58 PST" name="DDDT" finished-at="2024-01-18T01:17:16 PST" duration-ms="18219" status="PASS">
          <reporter-output>
          </reporter-output>
        </test-method> <!-- DDDT -->
        <test-method is-config="true" signature="After_TC_Failure(java.lang.reflect.Method,org.testng.ITestResult)[pri:0, instance:com.kavi.demo.TestCases.DDD@1737834]" started-at="2024-01-18T01:17:16 PST" name="After_TC_Failure" finished-at="2024-01-18T01:17:16 PST" duration-ms="2" status="PASS">
          <params>
            <param index="0">
              <value>
                <![CDATA[public void com.kavi.demo.TestCases.DDD.DDDT() throws java.lang.Exception]]>
              </value>
            </param>
            <param index="1">
              <value>
                <![CDATA[[TestResult name=DDDT status=SUCCESS method=DDD.DDDT()[pri:0, instance:com.kavi.demo.TestCases.DDD@1737834] output={null}]]]>
              </value>
            </param>
          </params>
          <reporter-output>
          </reporter-output>
        </test-method> <!-- After_TC_Failure -->
        <test-method is-config="true" signature="initializeReport(org.testng.ITestContext)[pri:0, instance:com.kavi.demo.TestCases.DDD@1737834]" started-at="2024-01-18T01:17:16 PST" name="initializeReport" finished-at="2024-01-18T01:17:16 PST" duration-ms="1" status="PASS">
          <params>
            <param index="0">
              <value>
                <![CDATA[org.testng.TestRunner@56082f59]]>
              </value>
            </param>
          </params>
          <reporter-output>
          </reporter-output>
        </test-method> <!-- initializeReport -->
        <test-method signature="DDDT()[pri:0, instance:com.kavi.demo.TestCases.DDD@1737834]" started-at="2024-01-18T01:17:16 PST" name="DDDT" finished-at="2024-01-18T01:17:30 PST" duration-ms="13626" status="FAIL">
          <exception class="java.lang.AssertionError">
            <message>
              <![CDATA[expected [https://qpot.omfysgroup.com/dashboard] but found [https://qpot.omfysgroup.com/]]]>
            </message>
            <full-stacktrace>
              <![CDATA[java.lang.AssertionError: expected [https://qpot.omfysgroup.com/dashboard] but found [https://qpot.omfysgroup.com/]
at org.testng.Assert.fail(Assert.java:110)
at org.testng.Assert.failNotEquals(Assert.java:1577)
at org.testng.Assert.assertEqualsImpl(Assert.java:149)
at org.testng.Assert.assertEquals(Assert.java:131)
at org.testng.Assert.assertEquals(Assert.java:655)
at org.testng.Assert.assertEquals(Assert.java:665)
at com.kavi.demo.TestCases.DDD.DDDT(DDD.java:56)
at java.base/jdk.internal.reflect.DirectMethodHandleAccessor.invoke(DirectMethodHandleAccessor.java:104)
at java.base/java.lang.reflect.Method.invoke(Method.java:578)
at org.testng.internal.invokers.MethodInvocationHelper.invokeMethod(MethodInvocationHelper.java:139)
at org.testng.internal.invokers.TestInvoker.invokeMethod(TestInvoker.java:677)
at org.testng.internal.invokers.TestInvoker.invokeTestMethod(TestInvoker.java:221)
at org.testng.internal.invokers.MethodRunner.runInSequence(MethodRunner.java:50)
at org.testng.internal.invokers.TestInvoker$MethodInvocationAgent.invoke(TestInvoker.java:969)
at org.testng.internal.invokers.TestInvoker.invokeTestMethods(TestInvoker.java:194)
at org.testng.internal.invokers.TestMethodWorker.invokeTestMethods(TestMethodWorker.java:148)
at org.testng.internal.invokers.TestMethodWorker.run(TestMethodWorker.java:128)
at java.base/java.util.ArrayList.forEach(ArrayList.java:1511)
at org.testng.TestRunner.privateRun(TestRunner.java:829)
at org.testng.TestRunner.run(TestRunner.java:602)
at org.testng.SuiteRunner.runTest(SuiteRunner.java:437)
at org.testng.SuiteRunner.runSequentially(SuiteRunner.java:431)
at org.testng.SuiteRunner.privateRun(SuiteRunner.java:391)
at org.testng.SuiteRunner.run(SuiteRunner.java:330)
at org.testng.SuiteRunnerWorker.runSuite(SuiteRunnerWorker.java:52)
at org.testng.SuiteRunnerWorker.run(SuiteRunnerWorker.java:95)
at org.testng.TestNG.runSuitesSequentially(TestNG.java:1256)
at org.testng.TestNG.runSuitesLocally(TestNG.java:1176)
at org.testng.TestNG.runSuites(TestNG.java:1099)
at org.testng.TestNG.run(TestNG.java:1067)
at org.testng.remote.AbstractRemoteTestNG.run(AbstractRemoteTestNG.java:115)
at org.testng.remote.RemoteTestNG.initAndRun(RemoteTestNG.java:251)
at org.testng.remote.RemoteTestNG.main(RemoteTestNG.java:77)
]]>
            </full-stacktrace>
          </exception> <!-- java.lang.AssertionError -->
          <reporter-output>
          </reporter-output>
        </test-method> <!-- DDDT -->
        <test-method is-config="true" signature="After_TC_Failure(java.lang.reflect.Method,org.testng.ITestResult)[pri:0, instance:com.kavi.demo.TestCases.DDD@1737834]" started-at="2024-01-18T01:17:30 PST" name="After_TC_Failure" finished-at="2024-01-18T01:17:30 PST" duration-ms="242" status="PASS">
          <params>
            <param index="0">
              <value>
                <![CDATA[public void com.kavi.demo.TestCases.DDD.DDDT() throws java.lang.Exception]]>
              </value>
            </param>
            <param index="1">
              <value>
                <![CDATA[[TestResult name=DDDT status=FAILURE method=DDD.DDDT()[pri:0, instance:com.kavi.demo.TestCases.DDD@1737834] output={null}]]]>
              </value>
            </param>
          </params>
          <reporter-output>
          </reporter-output>
        </test-method> <!-- After_TC_Failure -->
        <test-method is-config="true" signature="initializeReport(org.testng.ITestContext)[pri:0, instance:com.kavi.demo.TestCases.DDD@1737834]" started-at="2024-01-18T01:17:30 PST" name="initializeReport" finished-at="2024-01-18T01:17:30 PST" duration-ms="1" status="PASS">
          <params>
            <param index="0">
              <value>
                <![CDATA[org.testng.TestRunner@56082f59]]>
              </value>
            </param>
          </params>
          <reporter-output>
          </reporter-output>
        </test-method> <!-- initializeReport -->
        <test-method signature="DDDT()[pri:0, instance:com.kavi.demo.TestCases.DDD@1737834]" started-at="2024-01-18T01:17:30 PST" name="DDDT" finished-at="2024-01-18T01:17:44 PST" duration-ms="13505" status="FAIL">
          <exception class="java.lang.AssertionError">
            <message>
              <![CDATA[expected [https://qpot.omfysgroup.com/dashboard] but found [https://qpot.omfysgroup.com/]]]>
            </message>
            <full-stacktrace>
              <![CDATA[java.lang.AssertionError: expected [https://qpot.omfysgroup.com/dashboard] but found [https://qpot.omfysgroup.com/]
at org.testng.Assert.fail(Assert.java:110)
at org.testng.Assert.failNotEquals(Assert.java:1577)
at org.testng.Assert.assertEqualsImpl(Assert.java:149)
at org.testng.Assert.assertEquals(Assert.java:131)
at org.testng.Assert.assertEquals(Assert.java:655)
at org.testng.Assert.assertEquals(Assert.java:665)
at com.kavi.demo.TestCases.DDD.DDDT(DDD.java:56)
at java.base/jdk.internal.reflect.DirectMethodHandleAccessor.invoke(DirectMethodHandleAccessor.java:104)
at java.base/java.lang.reflect.Method.invoke(Method.java:578)
at org.testng.internal.invokers.MethodInvocationHelper.invokeMethod(MethodInvocationHelper.java:139)
at org.testng.internal.invokers.TestInvoker.invokeMethod(TestInvoker.java:677)
at org.testng.internal.invokers.TestInvoker.invokeTestMethod(TestInvoker.java:221)
at org.testng.internal.invokers.MethodRunner.runInSequence(MethodRunner.java:50)
at org.testng.internal.invokers.TestInvoker$MethodInvocationAgent.invoke(TestInvoker.java:969)
at org.testng.internal.invokers.TestInvoker.invokeTestMethods(TestInvoker.java:194)
at org.testng.internal.invokers.TestMethodWorker.invokeTestMethods(TestMethodWorker.java:148)
at org.testng.internal.invokers.TestMethodWorker.run(TestMethodWorker.java:128)
at java.base/java.util.ArrayList.forEach(ArrayList.java:1511)
at org.testng.TestRunner.privateRun(TestRunner.java:829)
at org.testng.TestRunner.run(TestRunner.java:602)
at org.testng.SuiteRunner.runTest(SuiteRunner.java:437)
at org.testng.SuiteRunner.runSequentially(SuiteRunner.java:431)
at org.testng.SuiteRunner.privateRun(SuiteRunner.java:391)
at org.testng.SuiteRunner.run(SuiteRunner.java:330)
at org.testng.SuiteRunnerWorker.runSuite(SuiteRunnerWorker.java:52)
at org.testng.SuiteRunnerWorker.run(SuiteRunnerWorker.java:95)
at org.testng.TestNG.runSuitesSequentially(TestNG.java:1256)
at org.testng.TestNG.runSuitesLocally(TestNG.java:1176)
at org.testng.TestNG.runSuites(TestNG.java:1099)
at org.testng.TestNG.run(TestNG.java:1067)
at org.testng.remote.AbstractRemoteTestNG.run(AbstractRemoteTestNG.java:115)
at org.testng.remote.RemoteTestNG.initAndRun(RemoteTestNG.java:251)
at org.testng.remote.RemoteTestNG.main(RemoteTestNG.java:77)
]]>
            </full-stacktrace>
          </exception> <!-- java.lang.AssertionError -->
          <reporter-output>
          </reporter-output>
        </test-method> <!-- DDDT -->
        <test-method is-config="true" signature="After_TC_Failure(java.lang.reflect.Method,org.testng.ITestResult)[pri:0, instance:com.kavi.demo.TestCases.DDD@1737834]" started-at="2024-01-18T01:17:44 PST" name="After_TC_Failure" finished-at="2024-01-18T01:17:44 PST" duration-ms="278" status="PASS">
          <params>
            <param index="0">
              <value>
                <![CDATA[public void com.kavi.demo.TestCases.DDD.DDDT() throws java.lang.Exception]]>
              </value>
            </param>
            <param index="1">
              <value>
                <![CDATA[[TestResult name=DDDT status=FAILURE method=DDD.DDDT()[pri:0, instance:com.kavi.demo.TestCases.DDD@1737834] output={null}]]]>
              </value>
            </param>
          </params>
          <reporter-output>
          </reporter-output>
        </test-method> <!-- After_TC_Failure -->
        <test-method is-config="true" signature="initializeReport(org.testng.ITestContext)[pri:0, instance:com.kavi.demo.TestCases.DDD@1737834]" started-at="2024-01-18T01:17:44 PST" name="initializeReport" finished-at="2024-01-18T01:17:44 PST" duration-ms="1" status="PASS">
          <params>
            <param index="0">
              <value>
                <![CDATA[org.testng.TestRunner@56082f59]]>
              </value>
            </param>
          </params>
          <reporter-output>
          </reporter-output>
        </test-method> <!-- initializeReport -->
        <test-method signature="DDDT()[pri:0, instance:com.kavi.demo.TestCases.DDD@1737834]" started-at="2024-01-18T01:17:44 PST" name="DDDT" finished-at="2024-01-18T01:17:55 PST" duration-ms="11363" status="FAIL">
          <exception class="java.lang.AssertionError">
            <message>
              <![CDATA[expected [https://qpot.omfysgroup.com/dashboard] but found [https://qpot.omfysgroup.com/]]]>
            </message>
            <full-stacktrace>
              <![CDATA[java.lang.AssertionError: expected [https://qpot.omfysgroup.com/dashboard] but found [https://qpot.omfysgroup.com/]
at org.testng.Assert.fail(Assert.java:110)
at org.testng.Assert.failNotEquals(Assert.java:1577)
at org.testng.Assert.assertEqualsImpl(Assert.java:149)
at org.testng.Assert.assertEquals(Assert.java:131)
at org.testng.Assert.assertEquals(Assert.java:655)
at org.testng.Assert.assertEquals(Assert.java:665)
at com.kavi.demo.TestCases.DDD.DDDT(DDD.java:126)
at java.base/jdk.internal.reflect.DirectMethodHandleAccessor.invoke(DirectMethodHandleAccessor.java:104)
at java.base/java.lang.reflect.Method.invoke(Method.java:578)
at org.testng.internal.invokers.MethodInvocationHelper.invokeMethod(MethodInvocationHelper.java:139)
at org.testng.internal.invokers.TestInvoker.invokeMethod(TestInvoker.java:677)
at org.testng.internal.invokers.TestInvoker.invokeTestMethod(TestInvoker.java:221)
at org.testng.internal.invokers.MethodRunner.runInSequence(MethodRunner.java:50)
at org.testng.internal.invokers.TestInvoker$MethodInvocationAgent.invoke(TestInvoker.java:969)
at org.testng.internal.invokers.TestInvoker.invokeTestMethods(TestInvoker.java:194)
at org.testng.internal.invokers.TestMethodWorker.invokeTestMethods(TestMethodWorker.java:148)
at org.testng.internal.invokers.TestMethodWorker.run(TestMethodWorker.java:128)
at java.base/java.util.ArrayList.forEach(ArrayList.java:1511)
at org.testng.TestRunner.privateRun(TestRunner.java:829)
at org.testng.TestRunner.run(TestRunner.java:602)
at org.testng.SuiteRunner.runTest(SuiteRunner.java:437)
at org.testng.SuiteRunner.runSequentially(SuiteRunner.java:431)
at org.testng.SuiteRunner.privateRun(SuiteRunner.java:391)
at org.testng.SuiteRunner.run(SuiteRunner.java:330)
at org.testng.SuiteRunnerWorker.runSuite(SuiteRunnerWorker.java:52)
at org.testng.SuiteRunnerWorker.run(SuiteRunnerWorker.java:95)
at org.testng.TestNG.runSuitesSequentially(TestNG.java:1256)
at org.testng.TestNG.runSuitesLocally(TestNG.java:1176)
at org.testng.TestNG.runSuites(TestNG.java:1099)
at org.testng.TestNG.run(TestNG.java:1067)
at org.testng.remote.AbstractRemoteTestNG.run(AbstractRemoteTestNG.java:115)
at org.testng.remote.RemoteTestNG.initAndRun(RemoteTestNG.java:251)
at org.testng.remote.RemoteTestNG.main(RemoteTestNG.java:77)
]]>
            </full-stacktrace>
          </exception> <!-- java.lang.AssertionError -->
          <reporter-output>
          </reporter-output>
        </test-method> <!-- DDDT -->
        <test-method is-config="true" signature="After_TC_Failure(java.lang.reflect.Method,org.testng.ITestResult)[pri:0, instance:com.kavi.demo.TestCases.DDD@1737834]" started-at="2024-01-18T01:17:55 PST" name="After_TC_Failure" finished-at="2024-01-18T01:17:56 PST" duration-ms="246" status="PASS">
          <params>
            <param index="0">
              <value>
                <![CDATA[public void com.kavi.demo.TestCases.DDD.DDDT() throws java.lang.Exception]]>
              </value>
            </param>
            <param index="1">
              <value>
                <![CDATA[[TestResult name=DDDT status=FAILURE method=DDD.DDDT()[pri:0, instance:com.kavi.demo.TestCases.DDD@1737834] output={null}]]]>
              </value>
            </param>
          </params>
          <reporter-output>
          </reporter-output>
        </test-method> <!-- After_TC_Failure -->
        <test-method is-config="true" signature="initializeReport(org.testng.ITestContext)[pri:0, instance:com.kavi.demo.TestCases.DDD@1737834]" started-at="2024-01-18T01:17:56 PST" name="initializeReport" finished-at="2024-01-18T01:17:56 PST" duration-ms="0" status="PASS">
          <params>
            <param index="0">
              <value>
                <![CDATA[org.testng.TestRunner@56082f59]]>
              </value>
            </param>
          </params>
          <reporter-output>
          </reporter-output>
        </test-method> <!-- initializeReport -->
        <test-method signature="DDDT()[pri:0, instance:com.kavi.demo.TestCases.DDD@1737834]" started-at="2024-01-18T01:17:56 PST" name="DDDT" finished-at="2024-01-18T01:18:09 PST" duration-ms="13331" status="FAIL">
          <exception class="java.lang.AssertionError">
            <message>
              <![CDATA[expected [https://qpot.omfysgroup.com/dashboard] but found [https://qpot.omfysgroup.com/]]]>
            </message>
            <full-stacktrace>
              <![CDATA[java.lang.AssertionError: expected [https://qpot.omfysgroup.com/dashboard] but found [https://qpot.omfysgroup.com/]
at org.testng.Assert.fail(Assert.java:110)
at org.testng.Assert.failNotEquals(Assert.java:1577)
at org.testng.Assert.assertEqualsImpl(Assert.java:149)
at org.testng.Assert.assertEquals(Assert.java:131)
at org.testng.Assert.assertEquals(Assert.java:655)
at org.testng.Assert.assertEquals(Assert.java:665)
at com.kavi.demo.TestCases.DDD.DDDT(DDD.java:91)
at java.base/jdk.internal.reflect.DirectMethodHandleAccessor.invoke(DirectMethodHandleAccessor.java:104)
at java.base/java.lang.reflect.Method.invoke(Method.java:578)
at org.testng.internal.invokers.MethodInvocationHelper.invokeMethod(MethodInvocationHelper.java:139)
at org.testng.internal.invokers.TestInvoker.invokeMethod(TestInvoker.java:677)
at org.testng.internal.invokers.TestInvoker.invokeTestMethod(TestInvoker.java:221)
at org.testng.internal.invokers.MethodRunner.runInSequence(MethodRunner.java:50)
at org.testng.internal.invokers.TestInvoker$MethodInvocationAgent.invoke(TestInvoker.java:969)
at org.testng.internal.invokers.TestInvoker.invokeTestMethods(TestInvoker.java:194)
at org.testng.internal.invokers.TestMethodWorker.invokeTestMethods(TestMethodWorker.java:148)
at org.testng.internal.invokers.TestMethodWorker.run(TestMethodWorker.java:128)
at java.base/java.util.ArrayList.forEach(ArrayList.java:1511)
at org.testng.TestRunner.privateRun(TestRunner.java:829)
at org.testng.TestRunner.run(TestRunner.java:602)
at org.testng.SuiteRunner.runTest(SuiteRunner.java:437)
at org.testng.SuiteRunner.runSequentially(SuiteRunner.java:431)
at org.testng.SuiteRunner.privateRun(SuiteRunner.java:391)
at org.testng.SuiteRunner.run(SuiteRunner.java:330)
at org.testng.SuiteRunnerWorker.runSuite(SuiteRunnerWorker.java:52)
at org.testng.SuiteRunnerWorker.run(SuiteRunnerWorker.java:95)
at org.testng.TestNG.runSuitesSequentially(TestNG.java:1256)
at org.testng.TestNG.runSuitesLocally(TestNG.java:1176)
at org.testng.TestNG.runSuites(TestNG.java:1099)
at org.testng.TestNG.run(TestNG.java:1067)
at org.testng.remote.AbstractRemoteTestNG.run(AbstractRemoteTestNG.java:115)
at org.testng.remote.RemoteTestNG.initAndRun(RemoteTestNG.java:251)
at org.testng.remote.RemoteTestNG.main(RemoteTestNG.java:77)
]]>
            </full-stacktrace>
          </exception> <!-- java.lang.AssertionError -->
          <reporter-output>
          </reporter-output>
        </test-method> <!-- DDDT -->
        <test-method is-config="true" signature="After_TC_Failure(java.lang.reflect.Method,org.testng.ITestResult)[pri:0, instance:com.kavi.demo.TestCases.DDD@1737834]" started-at="2024-01-18T01:18:09 PST" name="After_TC_Failure" finished-at="2024-01-18T01:18:09 PST" duration-ms="253" status="PASS">
          <params>
            <param index="0">
              <value>
                <![CDATA[public void com.kavi.demo.TestCases.DDD.DDDT() throws java.lang.Exception]]>
              </value>
            </param>
            <param index="1">
              <value>
                <![CDATA[[TestResult name=DDDT status=FAILURE method=DDD.DDDT()[pri:0, instance:com.kavi.demo.TestCases.DDD@1737834] output={null}]]]>
              </value>
            </param>
          </params>
          <reporter-output>
          </reporter-output>
        </test-method> <!-- After_TC_Failure -->
        <test-method is-config="true" signature="initializeReport(org.testng.ITestContext)[pri:0, instance:com.kavi.demo.TestCases.DDD@1737834]" started-at="2024-01-18T01:18:09 PST" name="initializeReport" finished-at="2024-01-18T01:18:09 PST" duration-ms="0" status="PASS">
          <params>
            <param index="0">
              <value>
                <![CDATA[org.testng.TestRunner@56082f59]]>
              </value>
            </param>
          </params>
          <reporter-output>
          </reporter-output>
        </test-method> <!-- initializeReport -->
        <test-method signature="DDDT()[pri:0, instance:com.kavi.demo.TestCases.DDD@1737834]" started-at="2024-01-18T01:18:09 PST" name="DDDT" finished-at="2024-01-18T01:18:23 PST" duration-ms="13449" status="FAIL">
          <exception class="java.lang.AssertionError">
            <message>
              <![CDATA[expected [https://qpot.omfysgroup.com/dashboard] but found [https://qpot.omfysgroup.com/]]]>
            </message>
            <full-stacktrace>
              <![CDATA[java.lang.AssertionError: expected [https://qpot.omfysgroup.com/dashboard] but found [https://qpot.omfysgroup.com/]
at org.testng.Assert.fail(Assert.java:110)
at org.testng.Assert.failNotEquals(Assert.java:1577)
at org.testng.Assert.assertEqualsImpl(Assert.java:149)
at org.testng.Assert.assertEquals(Assert.java:131)
at org.testng.Assert.assertEquals(Assert.java:655)
at org.testng.Assert.assertEquals(Assert.java:665)
at com.kavi.demo.TestCases.DDD.DDDT(DDD.java:56)
at java.base/jdk.internal.reflect.DirectMethodHandleAccessor.invoke(DirectMethodHandleAccessor.java:104)
at java.base/java.lang.reflect.Method.invoke(Method.java:578)
at org.testng.internal.invokers.MethodInvocationHelper.invokeMethod(MethodInvocationHelper.java:139)
at org.testng.internal.invokers.TestInvoker.invokeMethod(TestInvoker.java:677)
at org.testng.internal.invokers.TestInvoker.invokeTestMethod(TestInvoker.java:221)
at org.testng.internal.invokers.MethodRunner.runInSequence(MethodRunner.java:50)
at org.testng.internal.invokers.TestInvoker$MethodInvocationAgent.invoke(TestInvoker.java:969)
at org.testng.internal.invokers.TestInvoker.invokeTestMethods(TestInvoker.java:194)
at org.testng.internal.invokers.TestMethodWorker.invokeTestMethods(TestMethodWorker.java:148)
at org.testng.internal.invokers.TestMethodWorker.run(TestMethodWorker.java:128)
at java.base/java.util.ArrayList.forEach(ArrayList.java:1511)
at org.testng.TestRunner.privateRun(TestRunner.java:829)
at org.testng.TestRunner.run(TestRunner.java:602)
at org.testng.SuiteRunner.runTest(SuiteRunner.java:437)
at org.testng.SuiteRunner.runSequentially(SuiteRunner.java:431)
at org.testng.SuiteRunner.privateRun(SuiteRunner.java:391)
at org.testng.SuiteRunner.run(SuiteRunner.java:330)
at org.testng.SuiteRunnerWorker.runSuite(SuiteRunnerWorker.java:52)
at org.testng.SuiteRunnerWorker.run(SuiteRunnerWorker.java:95)
at org.testng.TestNG.runSuitesSequentially(TestNG.java:1256)
at org.testng.TestNG.runSuitesLocally(TestNG.java:1176)
at org.testng.TestNG.runSuites(TestNG.java:1099)
at org.testng.TestNG.run(TestNG.java:1067)
at org.testng.remote.AbstractRemoteTestNG.run(AbstractRemoteTestNG.java:115)
at org.testng.remote.RemoteTestNG.initAndRun(RemoteTestNG.java:251)
at org.testng.remote.RemoteTestNG.main(RemoteTestNG.java:77)
]]>
            </full-stacktrace>
          </exception> <!-- java.lang.AssertionError -->
          <reporter-output>
          </reporter-output>
        </test-method> <!-- DDDT -->
        <test-method is-config="true" signature="After_TC_Failure(java.lang.reflect.Method,org.testng.ITestResult)[pri:0, instance:com.kavi.demo.TestCases.DDD@1737834]" started-at="2024-01-18T01:18:23 PST" name="After_TC_Failure" finished-at="2024-01-18T01:18:23 PST" duration-ms="242" status="PASS">
          <params>
            <param index="0">
              <value>
                <![CDATA[public void com.kavi.demo.TestCases.DDD.DDDT() throws java.lang.Exception]]>
              </value>
            </param>
            <param index="1">
              <value>
                <![CDATA[[TestResult name=DDDT status=FAILURE method=DDD.DDDT()[pri:0, instance:com.kavi.demo.TestCases.DDD@1737834] output={null}]]]>
              </value>
            </param>
          </params>
          <reporter-output>
          </reporter-output>
        </test-method> <!-- After_TC_Failure -->
        <test-method is-config="true" signature="initializeReport(org.testng.ITestContext)[pri:0, instance:com.kavi.demo.TestCases.DDD@1737834]" started-at="2024-01-18T01:18:23 PST" name="initializeReport" finished-at="2024-01-18T01:18:23 PST" duration-ms="1" status="PASS">
          <params>
            <param index="0">
              <value>
                <![CDATA[org.testng.TestRunner@56082f59]]>
              </value>
            </param>
          </params>
          <reporter-output>
          </reporter-output>
        </test-method> <!-- initializeReport -->
        <test-method signature="DDDT()[pri:0, instance:com.kavi.demo.TestCases.DDD@1737834]" started-at="2024-01-18T01:18:23 PST" name="DDDT" finished-at="2024-01-18T01:18:36 PST" duration-ms="13422" status="FAIL">
          <exception class="java.lang.AssertionError">
            <message>
              <![CDATA[expected [https://qpot.omfysgroup.com/dashboard] but found [https://qpot.omfysgroup.com/]]]>
            </message>
            <full-stacktrace>
              <![CDATA[java.lang.AssertionError: expected [https://qpot.omfysgroup.com/dashboard] but found [https://qpot.omfysgroup.com/]
at org.testng.Assert.fail(Assert.java:110)
at org.testng.Assert.failNotEquals(Assert.java:1577)
at org.testng.Assert.assertEqualsImpl(Assert.java:149)
at org.testng.Assert.assertEquals(Assert.java:131)
at org.testng.Assert.assertEquals(Assert.java:655)
at org.testng.Assert.assertEquals(Assert.java:665)
at com.kavi.demo.TestCases.DDD.DDDT(DDD.java:56)
at java.base/jdk.internal.reflect.DirectMethodHandleAccessor.invoke(DirectMethodHandleAccessor.java:104)
at java.base/java.lang.reflect.Method.invoke(Method.java:578)
at org.testng.internal.invokers.MethodInvocationHelper.invokeMethod(MethodInvocationHelper.java:139)
at org.testng.internal.invokers.TestInvoker.invokeMethod(TestInvoker.java:677)
at org.testng.internal.invokers.TestInvoker.invokeTestMethod(TestInvoker.java:221)
at org.testng.internal.invokers.MethodRunner.runInSequence(MethodRunner.java:50)
at org.testng.internal.invokers.TestInvoker$MethodInvocationAgent.invoke(TestInvoker.java:969)
at org.testng.internal.invokers.TestInvoker.invokeTestMethods(TestInvoker.java:194)
at org.testng.internal.invokers.TestMethodWorker.invokeTestMethods(TestMethodWorker.java:148)
at org.testng.internal.invokers.TestMethodWorker.run(TestMethodWorker.java:128)
at java.base/java.util.ArrayList.forEach(ArrayList.java:1511)
at org.testng.TestRunner.privateRun(TestRunner.java:829)
at org.testng.TestRunner.run(TestRunner.java:602)
at org.testng.SuiteRunner.runTest(SuiteRunner.java:437)
at org.testng.SuiteRunner.runSequentially(SuiteRunner.java:431)
at org.testng.SuiteRunner.privateRun(SuiteRunner.java:391)
at org.testng.SuiteRunner.run(SuiteRunner.java:330)
at org.testng.SuiteRunnerWorker.runSuite(SuiteRunnerWorker.java:52)
at org.testng.SuiteRunnerWorker.run(SuiteRunnerWorker.java:95)
at org.testng.TestNG.runSuitesSequentially(TestNG.java:1256)
at org.testng.TestNG.runSuitesLocally(TestNG.java:1176)
at org.testng.TestNG.runSuites(TestNG.java:1099)
at org.testng.TestNG.run(TestNG.java:1067)
at org.testng.remote.AbstractRemoteTestNG.run(AbstractRemoteTestNG.java:115)
at org.testng.remote.RemoteTestNG.initAndRun(RemoteTestNG.java:251)
at org.testng.remote.RemoteTestNG.main(RemoteTestNG.java:77)
]]>
            </full-stacktrace>
          </exception> <!-- java.lang.AssertionError -->
          <reporter-output>
          </reporter-output>
        </test-method> <!-- DDDT -->
        <test-method is-config="true" signature="After_TC_Failure(java.lang.reflect.Method,org.testng.ITestResult)[pri:0, instance:com.kavi.demo.TestCases.DDD@1737834]" started-at="2024-01-18T01:18:36 PST" name="After_TC_Failure" finished-at="2024-01-18T01:18:37 PST" duration-ms="268" status="PASS">
          <params>
            <param index="0">
              <value>
                <![CDATA[public void com.kavi.demo.TestCases.DDD.DDDT() throws java.lang.Exception]]>
              </value>
            </param>
            <param index="1">
              <value>
                <![CDATA[[TestResult name=DDDT status=FAILURE method=DDD.DDDT()[pri:0, instance:com.kavi.demo.TestCases.DDD@1737834] output={null}]]]>
              </value>
            </param>
          </params>
          <reporter-output>
          </reporter-output>
        </test-method> <!-- After_TC_Failure -->
        <test-method is-config="true" signature="initializeReport(org.testng.ITestContext)[pri:0, instance:com.kavi.demo.TestCases.DDD@1737834]" started-at="2024-01-18T01:18:37 PST" name="initializeReport" finished-at="2024-01-18T01:18:37 PST" duration-ms="1" status="PASS">
          <params>
            <param index="0">
              <value>
                <![CDATA[org.testng.TestRunner@56082f59]]>
              </value>
            </param>
          </params>
          <reporter-output>
          </reporter-output>
        </test-method> <!-- initializeReport -->
        <test-method signature="DDDT()[pri:0, instance:com.kavi.demo.TestCases.DDD@1737834]" started-at="2024-01-18T01:18:37 PST" name="DDDT" finished-at="2024-01-18T01:18:50 PST" duration-ms="13386" status="FAIL">
          <exception class="java.lang.AssertionError">
            <message>
              <![CDATA[expected [https://qpot.omfysgroup.com/dashboard] but found [https://qpot.omfysgroup.com/]]]>
            </message>
            <full-stacktrace>
              <![CDATA[java.lang.AssertionError: expected [https://qpot.omfysgroup.com/dashboard] but found [https://qpot.omfysgroup.com/]
at org.testng.Assert.fail(Assert.java:110)
at org.testng.Assert.failNotEquals(Assert.java:1577)
at org.testng.Assert.assertEqualsImpl(Assert.java:149)
at org.testng.Assert.assertEquals(Assert.java:131)
at org.testng.Assert.assertEquals(Assert.java:655)
at org.testng.Assert.assertEquals(Assert.java:665)
at com.kavi.demo.TestCases.DDD.DDDT(DDD.java:56)
at java.base/jdk.internal.reflect.DirectMethodHandleAccessor.invoke(DirectMethodHandleAccessor.java:104)
at java.base/java.lang.reflect.Method.invoke(Method.java:578)
at org.testng.internal.invokers.MethodInvocationHelper.invokeMethod(MethodInvocationHelper.java:139)
at org.testng.internal.invokers.TestInvoker.invokeMethod(TestInvoker.java:677)
at org.testng.internal.invokers.TestInvoker.invokeTestMethod(TestInvoker.java:221)
at org.testng.internal.invokers.MethodRunner.runInSequence(MethodRunner.java:50)
at org.testng.internal.invokers.TestInvoker$MethodInvocationAgent.invoke(TestInvoker.java:969)
at org.testng.internal.invokers.TestInvoker.invokeTestMethods(TestInvoker.java:194)
at org.testng.internal.invokers.TestMethodWorker.invokeTestMethods(TestMethodWorker.java:148)
at org.testng.internal.invokers.TestMethodWorker.run(TestMethodWorker.java:128)
at java.base/java.util.ArrayList.forEach(ArrayList.java:1511)
at org.testng.TestRunner.privateRun(TestRunner.java:829)
at org.testng.TestRunner.run(TestRunner.java:602)
at org.testng.SuiteRunner.runTest(SuiteRunner.java:437)
at org.testng.SuiteRunner.runSequentially(SuiteRunner.java:431)
at org.testng.SuiteRunner.privateRun(SuiteRunner.java:391)
at org.testng.SuiteRunner.run(SuiteRunner.java:330)
at org.testng.SuiteRunnerWorker.runSuite(SuiteRunnerWorker.java:52)
at org.testng.SuiteRunnerWorker.run(SuiteRunnerWorker.java:95)
at org.testng.TestNG.runSuitesSequentially(TestNG.java:1256)
at org.testng.TestNG.runSuitesLocally(TestNG.java:1176)
at org.testng.TestNG.runSuites(TestNG.java:1099)
at org.testng.TestNG.run(TestNG.java:1067)
at org.testng.remote.AbstractRemoteTestNG.run(AbstractRemoteTestNG.java:115)
at org.testng.remote.RemoteTestNG.initAndRun(RemoteTestNG.java:251)
at org.testng.remote.RemoteTestNG.main(RemoteTestNG.java:77)
]]>
            </full-stacktrace>
          </exception> <!-- java.lang.AssertionError -->
          <reporter-output>
          </reporter-output>
        </test-method> <!-- DDDT -->
        <test-method is-config="true" signature="After_TC_Failure(java.lang.reflect.Method,org.testng.ITestResult)[pri:0, instance:com.kavi.demo.TestCases.DDD@1737834]" started-at="2024-01-18T01:18:50 PST" name="After_TC_Failure" finished-at="2024-01-18T01:18:50 PST" duration-ms="282" status="PASS">
          <params>
            <param index="0">
              <value>
                <![CDATA[public void com.kavi.demo.TestCases.DDD.DDDT() throws java.lang.Exception]]>
              </value>
            </param>
            <param index="1">
              <value>
                <![CDATA[[TestResult name=DDDT status=FAILURE method=DDD.DDDT()[pri:0, instance:com.kavi.demo.TestCases.DDD@1737834] output={null}]]]>
              </value>
            </param>
          </params>
          <reporter-output>
          </reporter-output>
        </test-method> <!-- After_TC_Failure -->
        <test-method is-config="true" signature="initializeReport(org.testng.ITestContext)[pri:0, instance:com.kavi.demo.TestCases.DDD@1737834]" started-at="2024-01-18T01:18:50 PST" name="initializeReport" finished-at="2024-01-18T01:18:50 PST" duration-ms="1" status="PASS">
          <params>
            <param index="0">
              <value>
                <![CDATA[org.testng.TestRunner@56082f59]]>
              </value>
            </param>
          </params>
          <reporter-output>
          </reporter-output>
        </test-method> <!-- initializeReport -->
        <test-method signature="DDDT()[pri:0, instance:com.kavi.demo.TestCases.DDD@1737834]" started-at="2024-01-18T01:18:50 PST" name="DDDT" finished-at="2024-01-18T01:19:02 PST" duration-ms="11203" status="FAIL">
          <exception class="java.lang.AssertionError">
            <message>
              <![CDATA[expected [https://qpot.omfysgroup.com/dashboard] but found [https://qpot.omfysgroup.com/]]]>
            </message>
            <full-stacktrace>
              <![CDATA[java.lang.AssertionError: expected [https://qpot.omfysgroup.com/dashboard] but found [https://qpot.omfysgroup.com/]
at org.testng.Assert.fail(Assert.java:110)
at org.testng.Assert.failNotEquals(Assert.java:1577)
at org.testng.Assert.assertEqualsImpl(Assert.java:149)
at org.testng.Assert.assertEquals(Assert.java:131)
at org.testng.Assert.assertEquals(Assert.java:655)
at org.testng.Assert.assertEquals(Assert.java:665)
at com.kavi.demo.TestCases.DDD.DDDT(DDD.java:158)
at java.base/jdk.internal.reflect.DirectMethodHandleAccessor.invoke(DirectMethodHandleAccessor.java:104)
at java.base/java.lang.reflect.Method.invoke(Method.java:578)
at org.testng.internal.invokers.MethodInvocationHelper.invokeMethod(MethodInvocationHelper.java:139)
at org.testng.internal.invokers.TestInvoker.invokeMethod(TestInvoker.java:677)
at org.testng.internal.invokers.TestInvoker.invokeTestMethod(TestInvoker.java:221)
at org.testng.internal.invokers.MethodRunner.runInSequence(MethodRunner.java:50)
at org.testng.internal.invokers.TestInvoker$MethodInvocationAgent.invoke(TestInvoker.java:969)
at org.testng.internal.invokers.TestInvoker.invokeTestMethods(TestInvoker.java:194)
at org.testng.internal.invokers.TestMethodWorker.invokeTestMethods(TestMethodWorker.java:148)
at org.testng.internal.invokers.TestMethodWorker.run(TestMethodWorker.java:128)
at java.base/java.util.ArrayList.forEach(ArrayList.java:1511)
at org.testng.TestRunner.privateRun(TestRunner.java:829)
at org.testng.TestRunner.run(TestRunner.java:602)
at org.testng.SuiteRunner.runTest(SuiteRunner.java:437)
at org.testng.SuiteRunner.runSequentially(SuiteRunner.java:431)
at org.testng.SuiteRunner.privateRun(SuiteRunner.java:391)
at org.testng.SuiteRunner.run(SuiteRunner.java:330)
at org.testng.SuiteRunnerWorker.runSuite(SuiteRunnerWorker.java:52)
at org.testng.SuiteRunnerWorker.run(SuiteRunnerWorker.java:95)
at org.testng.TestNG.runSuitesSequentially(TestNG.java:1256)
at org.testng.TestNG.runSuitesLocally(TestNG.java:1176)
at org.testng.TestNG.runSuites(TestNG.java:1099)
at org.testng.TestNG.run(TestNG.java:1067)
at org.testng.remote.AbstractRemoteTestNG.run(AbstractRemoteTestNG.java:115)
at org.testng.remote.RemoteTestNG.initAndRun(RemoteTestNG.java:251)
at org.testng.remote.RemoteTestNG.main(RemoteTestNG.java:77)
]]>
            </full-stacktrace>
          </exception> <!-- java.lang.AssertionError -->
          <reporter-output>
          </reporter-output>
        </test-method> <!-- DDDT -->
        <test-method is-config="true" signature="After_TC_Failure(java.lang.reflect.Method,org.testng.ITestResult)[pri:0, instance:com.kavi.demo.TestCases.DDD@1737834]" started-at="2024-01-18T01:19:02 PST" name="After_TC_Failure" finished-at="2024-01-18T01:19:02 PST" duration-ms="260" status="PASS">
          <params>
            <param index="0">
              <value>
                <![CDATA[public void com.kavi.demo.TestCases.DDD.DDDT() throws java.lang.Exception]]>
              </value>
            </param>
            <param index="1">
              <value>
                <![CDATA[[TestResult name=DDDT status=FAILURE method=DDD.DDDT()[pri:0, instance:com.kavi.demo.TestCases.DDD@1737834] output={null}]]]>
              </value>
            </param>
          </params>
          <reporter-output>
          </reporter-output>
        </test-method> <!-- After_TC_Failure -->
        <test-method is-config="true" signature="initializeReport(org.testng.ITestContext)[pri:0, instance:com.kavi.demo.TestCases.DDD@1737834]" started-at="2024-01-18T01:19:02 PST" name="initializeReport" finished-at="2024-01-18T01:19:02 PST" duration-ms="1" status="PASS">
          <params>
            <param index="0">
              <value>
                <![CDATA[org.testng.TestRunner@56082f59]]>
              </value>
            </param>
          </params>
          <reporter-output>
          </reporter-output>
        </test-method> <!-- initializeReport -->
        <test-method signature="DDDT()[pri:0, instance:com.kavi.demo.TestCases.DDD@1737834]" started-at="2024-01-18T01:19:02 PST" name="DDDT" finished-at="2024-01-18T01:19:13 PST" duration-ms="11178" status="FAIL">
          <exception class="java.lang.AssertionError">
            <message>
              <![CDATA[expected [https://qpot.omfysgroup.com/dashboard] but found [https://qpot.omfysgroup.com/]]]>
            </message>
            <full-stacktrace>
              <![CDATA[java.lang.AssertionError: expected [https://qpot.omfysgroup.com/dashboard] but found [https://qpot.omfysgroup.com/]
at org.testng.Assert.fail(Assert.java:110)
at org.testng.Assert.failNotEquals(Assert.java:1577)
at org.testng.Assert.assertEqualsImpl(Assert.java:149)
at org.testng.Assert.assertEquals(Assert.java:131)
at org.testng.Assert.assertEquals(Assert.java:655)
at org.testng.Assert.assertEquals(Assert.java:665)
at com.kavi.demo.TestCases.DDD.DDDT(DDD.java:158)
at java.base/jdk.internal.reflect.DirectMethodHandleAccessor.invoke(DirectMethodHandleAccessor.java:104)
at java.base/java.lang.reflect.Method.invoke(Method.java:578)
at org.testng.internal.invokers.MethodInvocationHelper.invokeMethod(MethodInvocationHelper.java:139)
at org.testng.internal.invokers.TestInvoker.invokeMethod(TestInvoker.java:677)
at org.testng.internal.invokers.TestInvoker.invokeTestMethod(TestInvoker.java:221)
at org.testng.internal.invokers.MethodRunner.runInSequence(MethodRunner.java:50)
at org.testng.internal.invokers.TestInvoker$MethodInvocationAgent.invoke(TestInvoker.java:969)
at org.testng.internal.invokers.TestInvoker.invokeTestMethods(TestInvoker.java:194)
at org.testng.internal.invokers.TestMethodWorker.invokeTestMethods(TestMethodWorker.java:148)
at org.testng.internal.invokers.TestMethodWorker.run(TestMethodWorker.java:128)
at java.base/java.util.ArrayList.forEach(ArrayList.java:1511)
at org.testng.TestRunner.privateRun(TestRunner.java:829)
at org.testng.TestRunner.run(TestRunner.java:602)
at org.testng.SuiteRunner.runTest(SuiteRunner.java:437)
at org.testng.SuiteRunner.runSequentially(SuiteRunner.java:431)
at org.testng.SuiteRunner.privateRun(SuiteRunner.java:391)
at org.testng.SuiteRunner.run(SuiteRunner.java:330)
at org.testng.SuiteRunnerWorker.runSuite(SuiteRunnerWorker.java:52)
at org.testng.SuiteRunnerWorker.run(SuiteRunnerWorker.java:95)
at org.testng.TestNG.runSuitesSequentially(TestNG.java:1256)
at org.testng.TestNG.runSuitesLocally(TestNG.java:1176)
at org.testng.TestNG.runSuites(TestNG.java:1099)
at org.testng.TestNG.run(TestNG.java:1067)
at org.testng.remote.AbstractRemoteTestNG.run(AbstractRemoteTestNG.java:115)
at org.testng.remote.RemoteTestNG.initAndRun(RemoteTestNG.java:251)
at org.testng.remote.RemoteTestNG.main(RemoteTestNG.java:77)
]]>
            </full-stacktrace>
          </exception> <!-- java.lang.AssertionError -->
          <reporter-output>
          </reporter-output>
        </test-method> <!-- DDDT -->
        <test-method is-config="true" signature="After_TC_Failure(java.lang.reflect.Method,org.testng.ITestResult)[pri:0, instance:com.kavi.demo.TestCases.DDD@1737834]" started-at="2024-01-18T01:19:13 PST" name="After_TC_Failure" finished-at="2024-01-18T01:19:13 PST" duration-ms="259" status="PASS">
          <params>
            <param index="0">
              <value>
                <![CDATA[public void com.kavi.demo.TestCases.DDD.DDDT() throws java.lang.Exception]]>
              </value>
            </param>
            <param index="1">
              <value>
                <![CDATA[[TestResult name=DDDT status=FAILURE method=DDD.DDDT()[pri:0, instance:com.kavi.demo.TestCases.DDD@1737834] output={null}]]]>
              </value>
            </param>
          </params>
          <reporter-output>
          </reporter-output>
        </test-method> <!-- After_TC_Failure -->
        <test-method is-config="true" signature="initializeReport(org.testng.ITestContext)[pri:0, instance:com.kavi.demo.TestCases.DDD@1737834]" started-at="2024-01-18T01:19:13 PST" name="initializeReport" finished-at="2024-01-18T01:19:13 PST" duration-ms="0" status="PASS">
          <params>
            <param index="0">
              <value>
                <![CDATA[org.testng.TestRunner@56082f59]]>
              </value>
            </param>
          </params>
          <reporter-output>
          </reporter-output>
        </test-method> <!-- initializeReport -->
        <test-method signature="DDDT()[pri:0, instance:com.kavi.demo.TestCases.DDD@1737834]" started-at="2024-01-18T01:19:13 PST" name="DDDT" finished-at="2024-01-18T01:19:24 PST" duration-ms="11181" status="FAIL">
          <exception class="java.lang.AssertionError">
            <message>
              <![CDATA[expected [https://qpot.omfysgroup.com/dashboard] but found [https://qpot.omfysgroup.com/]]]>
            </message>
            <full-stacktrace>
              <![CDATA[java.lang.AssertionError: expected [https://qpot.omfysgroup.com/dashboard] but found [https://qpot.omfysgroup.com/]
at org.testng.Assert.fail(Assert.java:110)
at org.testng.Assert.failNotEquals(Assert.java:1577)
at org.testng.Assert.assertEqualsImpl(Assert.java:149)
at org.testng.Assert.assertEquals(Assert.java:131)
at org.testng.Assert.assertEquals(Assert.java:655)
at org.testng.Assert.assertEquals(Assert.java:665)
at com.kavi.demo.TestCases.DDD.DDDT(DDD.java:158)
at java.base/jdk.internal.reflect.DirectMethodHandleAccessor.invoke(DirectMethodHandleAccessor.java:104)
at java.base/java.lang.reflect.Method.invoke(Method.java:578)
at org.testng.internal.invokers.MethodInvocationHelper.invokeMethod(MethodInvocationHelper.java:139)
at org.testng.internal.invokers.TestInvoker.invokeMethod(TestInvoker.java:677)
at org.testng.internal.invokers.TestInvoker.invokeTestMethod(TestInvoker.java:221)
at org.testng.internal.invokers.MethodRunner.runInSequence(MethodRunner.java:50)
at org.testng.internal.invokers.TestInvoker$MethodInvocationAgent.invoke(TestInvoker.java:969)
at org.testng.internal.invokers.TestInvoker.invokeTestMethods(TestInvoker.java:194)
at org.testng.internal.invokers.TestMethodWorker.invokeTestMethods(TestMethodWorker.java:148)
at org.testng.internal.invokers.TestMethodWorker.run(TestMethodWorker.java:128)
at java.base/java.util.ArrayList.forEach(ArrayList.java:1511)
at org.testng.TestRunner.privateRun(TestRunner.java:829)
at org.testng.TestRunner.run(TestRunner.java:602)
at org.testng.SuiteRunner.runTest(SuiteRunner.java:437)
at org.testng.SuiteRunner.runSequentially(SuiteRunner.java:431)
at org.testng.SuiteRunner.privateRun(SuiteRunner.java:391)
at org.testng.SuiteRunner.run(SuiteRunner.java:330)
at org.testng.SuiteRunnerWorker.runSuite(SuiteRunnerWorker.java:52)
at org.testng.SuiteRunnerWorker.run(SuiteRunnerWorker.java:95)
at org.testng.TestNG.runSuitesSequentially(TestNG.java:1256)
at org.testng.TestNG.runSuitesLocally(TestNG.java:1176)
at org.testng.TestNG.runSuites(TestNG.java:1099)
at org.testng.TestNG.run(TestNG.java:1067)
at org.testng.remote.AbstractRemoteTestNG.run(AbstractRemoteTestNG.java:115)
at org.testng.remote.RemoteTestNG.initAndRun(RemoteTestNG.java:251)
at org.testng.remote.RemoteTestNG.main(RemoteTestNG.java:77)
]]>
            </full-stacktrace>
          </exception> <!-- java.lang.AssertionError -->
          <reporter-output>
          </reporter-output>
        </test-method> <!-- DDDT -->
        <test-method is-config="true" signature="After_TC_Failure(java.lang.reflect.Method,org.testng.ITestResult)[pri:0, instance:com.kavi.demo.TestCases.DDD@1737834]" started-at="2024-01-18T01:19:24 PST" name="After_TC_Failure" finished-at="2024-01-18T01:19:25 PST" duration-ms="263" status="PASS">
          <params>
            <param index="0">
              <value>
                <![CDATA[public void com.kavi.demo.TestCases.DDD.DDDT() throws java.lang.Exception]]>
              </value>
            </param>
            <param index="1">
              <value>
                <![CDATA[[TestResult name=DDDT status=FAILURE method=DDD.DDDT()[pri:0, instance:com.kavi.demo.TestCases.DDD@1737834] output={null}]]]>
              </value>
            </param>
          </params>
          <reporter-output>
          </reporter-output>
        </test-method> <!-- After_TC_Failure -->
        <test-method is-config="true" signature="initializeReport(org.testng.ITestContext)[pri:0, instance:com.kavi.demo.TestCases.DDD@1737834]" started-at="2024-01-18T01:19:25 PST" name="initializeReport" finished-at="2024-01-18T01:19:25 PST" duration-ms="0" status="PASS">
          <params>
            <param index="0">
              <value>
                <![CDATA[org.testng.TestRunner@56082f59]]>
              </value>
            </param>
          </params>
          <reporter-output>
          </reporter-output>
        </test-method> <!-- initializeReport -->
        <test-method signature="DDDT()[pri:0, instance:com.kavi.demo.TestCases.DDD@1737834]" started-at="2024-01-18T01:19:25 PST" name="DDDT" finished-at="2024-01-18T01:19:36 PST" duration-ms="11166" status="FAIL">
          <exception class="java.lang.AssertionError">
            <message>
              <![CDATA[expected [https://qpot.omfysgroup.com/dashboard] but found [https://qpot.omfysgroup.com/]]]>
            </message>
            <full-stacktrace>
              <![CDATA[java.lang.AssertionError: expected [https://qpot.omfysgroup.com/dashboard] but found [https://qpot.omfysgroup.com/]
at org.testng.Assert.fail(Assert.java:110)
at org.testng.Assert.failNotEquals(Assert.java:1577)
at org.testng.Assert.assertEqualsImpl(Assert.java:149)
at org.testng.Assert.assertEquals(Assert.java:131)
at org.testng.Assert.assertEquals(Assert.java:655)
at org.testng.Assert.assertEquals(Assert.java:665)
at com.kavi.demo.TestCases.DDD.DDDT(DDD.java:158)
at java.base/jdk.internal.reflect.DirectMethodHandleAccessor.invoke(DirectMethodHandleAccessor.java:104)
at java.base/java.lang.reflect.Method.invoke(Method.java:578)
at org.testng.internal.invokers.MethodInvocationHelper.invokeMethod(MethodInvocationHelper.java:139)
at org.testng.internal.invokers.TestInvoker.invokeMethod(TestInvoker.java:677)
at org.testng.internal.invokers.TestInvoker.invokeTestMethod(TestInvoker.java:221)
at org.testng.internal.invokers.MethodRunner.runInSequence(MethodRunner.java:50)
at org.testng.internal.invokers.TestInvoker$MethodInvocationAgent.invoke(TestInvoker.java:969)
at org.testng.internal.invokers.TestInvoker.invokeTestMethods(TestInvoker.java:194)
at org.testng.internal.invokers.TestMethodWorker.invokeTestMethods(TestMethodWorker.java:148)
at org.testng.internal.invokers.TestMethodWorker.run(TestMethodWorker.java:128)
at java.base/java.util.ArrayList.forEach(ArrayList.java:1511)
at org.testng.TestRunner.privateRun(TestRunner.java:829)
at org.testng.TestRunner.run(TestRunner.java:602)
at org.testng.SuiteRunner.runTest(SuiteRunner.java:437)
at org.testng.SuiteRunner.runSequentially(SuiteRunner.java:431)
at org.testng.SuiteRunner.privateRun(SuiteRunner.java:391)
at org.testng.SuiteRunner.run(SuiteRunner.java:330)
at org.testng.SuiteRunnerWorker.runSuite(SuiteRunnerWorker.java:52)
at org.testng.SuiteRunnerWorker.run(SuiteRunnerWorker.java:95)
at org.testng.TestNG.runSuitesSequentially(TestNG.java:1256)
at org.testng.TestNG.runSuitesLocally(TestNG.java:1176)
at org.testng.TestNG.runSuites(TestNG.java:1099)
at org.testng.TestNG.run(TestNG.java:1067)
at org.testng.remote.AbstractRemoteTestNG.run(AbstractRemoteTestNG.java:115)
at org.testng.remote.RemoteTestNG.initAndRun(RemoteTestNG.java:251)
at org.testng.remote.RemoteTestNG.main(RemoteTestNG.java:77)
]]>
            </full-stacktrace>
          </exception> <!-- java.lang.AssertionError -->
          <reporter-output>
          </reporter-output>
        </test-method> <!-- DDDT -->
        <test-method is-config="true" signature="After_TC_Failure(java.lang.reflect.Method,org.testng.ITestResult)[pri:0, instance:com.kavi.demo.TestCases.DDD@1737834]" started-at="2024-01-18T01:19:36 PST" name="After_TC_Failure" finished-at="2024-01-18T01:19:36 PST" duration-ms="252" status="PASS">
          <params>
            <param index="0">
              <value>
                <![CDATA[public void com.kavi.demo.TestCases.DDD.DDDT() throws java.lang.Exception]]>
              </value>
            </param>
            <param index="1">
              <value>
                <![CDATA[[TestResult name=DDDT status=FAILURE method=DDD.DDDT()[pri:0, instance:com.kavi.demo.TestCases.DDD@1737834] output={null}]]]>
              </value>
            </param>
          </params>
          <reporter-output>
          </reporter-output>
        </test-method> <!-- After_TC_Failure -->
        <test-method is-config="true" signature="initializeReport(org.testng.ITestContext)[pri:0, instance:com.kavi.demo.TestCases.DDD@1737834]" started-at="2024-01-18T01:19:36 PST" name="initializeReport" finished-at="2024-01-18T01:19:36 PST" duration-ms="1" status="PASS">
          <params>
            <param index="0">
              <value>
                <![CDATA[org.testng.TestRunner@56082f59]]>
              </value>
            </param>
          </params>
          <reporter-output>
          </reporter-output>
        </test-method> <!-- initializeReport -->
        <test-method signature="DDDT()[pri:0, instance:com.kavi.demo.TestCases.DDD@1737834]" started-at="2024-01-18T01:19:36 PST" name="DDDT" finished-at="2024-01-18T01:19:47 PST" duration-ms="11181" status="FAIL">
          <exception class="java.lang.AssertionError">
            <message>
              <![CDATA[expected [https://qpot.omfysgroup.com/dashboard] but found [https://qpot.omfysgroup.com/]]]>
            </message>
            <full-stacktrace>
              <![CDATA[java.lang.AssertionError: expected [https://qpot.omfysgroup.com/dashboard] but found [https://qpot.omfysgroup.com/]
at org.testng.Assert.fail(Assert.java:110)
at org.testng.Assert.failNotEquals(Assert.java:1577)
at org.testng.Assert.assertEqualsImpl(Assert.java:149)
at org.testng.Assert.assertEquals(Assert.java:131)
at org.testng.Assert.assertEquals(Assert.java:655)
at org.testng.Assert.assertEquals(Assert.java:665)
at com.kavi.demo.TestCases.DDD.DDDT(DDD.java:158)
at java.base/jdk.internal.reflect.DirectMethodHandleAccessor.invoke(DirectMethodHandleAccessor.java:104)
at java.base/java.lang.reflect.Method.invoke(Method.java:578)
at org.testng.internal.invokers.MethodInvocationHelper.invokeMethod(MethodInvocationHelper.java:139)
at org.testng.internal.invokers.TestInvoker.invokeMethod(TestInvoker.java:677)
at org.testng.internal.invokers.TestInvoker.invokeTestMethod(TestInvoker.java:221)
at org.testng.internal.invokers.MethodRunner.runInSequence(MethodRunner.java:50)
at org.testng.internal.invokers.TestInvoker$MethodInvocationAgent.invoke(TestInvoker.java:969)
at org.testng.internal.invokers.TestInvoker.invokeTestMethods(TestInvoker.java:194)
at org.testng.internal.invokers.TestMethodWorker.invokeTestMethods(TestMethodWorker.java:148)
at org.testng.internal.invokers.TestMethodWorker.run(TestMethodWorker.java:128)
at java.base/java.util.ArrayList.forEach(ArrayList.java:1511)
at org.testng.TestRunner.privateRun(TestRunner.java:829)
at org.testng.TestRunner.run(TestRunner.java:602)
at org.testng.SuiteRunner.runTest(SuiteRunner.java:437)
at org.testng.SuiteRunner.runSequentially(SuiteRunner.java:431)
at org.testng.SuiteRunner.privateRun(SuiteRunner.java:391)
at org.testng.SuiteRunner.run(SuiteRunner.java:330)
at org.testng.SuiteRunnerWorker.runSuite(SuiteRunnerWorker.java:52)
at org.testng.SuiteRunnerWorker.run(SuiteRunnerWorker.java:95)
at org.testng.TestNG.runSuitesSequentially(TestNG.java:1256)
at org.testng.TestNG.runSuitesLocally(TestNG.java:1176)
at org.testng.TestNG.runSuites(TestNG.java:1099)
at org.testng.TestNG.run(TestNG.java:1067)
at org.testng.remote.AbstractRemoteTestNG.run(AbstractRemoteTestNG.java:115)
at org.testng.remote.RemoteTestNG.initAndRun(RemoteTestNG.java:251)
at org.testng.remote.RemoteTestNG.main(RemoteTestNG.java:77)
]]>
            </full-stacktrace>
          </exception> <!-- java.lang.AssertionError -->
          <reporter-output>
          </reporter-output>
        </test-method> <!-- DDDT -->
        <test-method is-config="true" signature="After_TC_Failure(java.lang.reflect.Method,org.testng.ITestResult)[pri:0, instance:com.kavi.demo.TestCases.DDD@1737834]" started-at="2024-01-18T01:19:47 PST" name="After_TC_Failure" finished-at="2024-01-18T01:19:48 PST" duration-ms="252" status="PASS">
          <params>
            <param index="0">
              <value>
                <![CDATA[public void com.kavi.demo.TestCases.DDD.DDDT() throws java.lang.Exception]]>
              </value>
            </param>
            <param index="1">
              <value>
                <![CDATA[[TestResult name=DDDT status=FAILURE method=DDD.DDDT()[pri:0, instance:com.kavi.demo.TestCases.DDD@1737834] output={null}]]]>
              </value>
            </param>
          </params>
          <reporter-output>
          </reporter-output>
        </test-method> <!-- After_TC_Failure -->
        <test-method is-config="true" signature="initializeReport(org.testng.ITestContext)[pri:0, instance:com.kavi.demo.TestCases.DDD@1737834]" started-at="2024-01-18T01:19:48 PST" name="initializeReport" finished-at="2024-01-18T01:19:48 PST" duration-ms="1" status="PASS">
          <params>
            <param index="0">
              <value>
                <![CDATA[org.testng.TestRunner@56082f59]]>
              </value>
            </param>
          </params>
          <reporter-output>
          </reporter-output>
        </test-method> <!-- initializeReport -->
        <test-method signature="DDDT()[pri:0, instance:com.kavi.demo.TestCases.DDD@1737834]" started-at="2024-01-18T01:19:48 PST" name="DDDT" finished-at="2024-01-18T01:19:59 PST" duration-ms="11162" status="FAIL">
          <exception class="java.lang.AssertionError">
            <message>
              <![CDATA[expected [https://qpot.omfysgroup.com/dashboard] but found [https://qpot.omfysgroup.com/]]]>
            </message>
            <full-stacktrace>
              <![CDATA[java.lang.AssertionError: expected [https://qpot.omfysgroup.com/dashboard] but found [https://qpot.omfysgroup.com/]
at org.testng.Assert.fail(Assert.java:110)
at org.testng.Assert.failNotEquals(Assert.java:1577)
at org.testng.Assert.assertEqualsImpl(Assert.java:149)
at org.testng.Assert.assertEquals(Assert.java:131)
at org.testng.Assert.assertEquals(Assert.java:655)
at org.testng.Assert.assertEquals(Assert.java:665)
at com.kavi.demo.TestCases.DDD.DDDT(DDD.java:158)
at java.base/jdk.internal.reflect.DirectMethodHandleAccessor.invoke(DirectMethodHandleAccessor.java:104)
at java.base/java.lang.reflect.Method.invoke(Method.java:578)
at org.testng.internal.invokers.MethodInvocationHelper.invokeMethod(MethodInvocationHelper.java:139)
at org.testng.internal.invokers.TestInvoker.invokeMethod(TestInvoker.java:677)
at org.testng.internal.invokers.TestInvoker.invokeTestMethod(TestInvoker.java:221)
at org.testng.internal.invokers.MethodRunner.runInSequence(MethodRunner.java:50)
at org.testng.internal.invokers.TestInvoker$MethodInvocationAgent.invoke(TestInvoker.java:969)
at org.testng.internal.invokers.TestInvoker.invokeTestMethods(TestInvoker.java:194)
at org.testng.internal.invokers.TestMethodWorker.invokeTestMethods(TestMethodWorker.java:148)
at org.testng.internal.invokers.TestMethodWorker.run(TestMethodWorker.java:128)
at java.base/java.util.ArrayList.forEach(ArrayList.java:1511)
at org.testng.TestRunner.privateRun(TestRunner.java:829)
at org.testng.TestRunner.run(TestRunner.java:602)
at org.testng.SuiteRunner.runTest(SuiteRunner.java:437)
at org.testng.SuiteRunner.runSequentially(SuiteRunner.java:431)
at org.testng.SuiteRunner.privateRun(SuiteRunner.java:391)
at org.testng.SuiteRunner.run(SuiteRunner.java:330)
at org.testng.SuiteRunnerWorker.runSuite(SuiteRunnerWorker.java:52)
at org.testng.SuiteRunnerWorker.run(SuiteRunnerWorker.java:95)
at org.testng.TestNG.runSuitesSequentially(TestNG.java:1256)
at org.testng.TestNG.runSuitesLocally(TestNG.java:1176)
at org.testng.TestNG.runSuites(TestNG.java:1099)
at org.testng.TestNG.run(TestNG.java:1067)
at org.testng.remote.AbstractRemoteTestNG.run(AbstractRemoteTestNG.java:115)
at org.testng.remote.RemoteTestNG.initAndRun(RemoteTestNG.java:251)
at org.testng.remote.RemoteTestNG.main(RemoteTestNG.java:77)
]]>
            </full-stacktrace>
          </exception> <!-- java.lang.AssertionError -->
          <reporter-output>
          </reporter-output>
        </test-method> <!-- DDDT -->
        <test-method is-config="true" signature="After_TC_Failure(java.lang.reflect.Method,org.testng.ITestResult)[pri:0, instance:com.kavi.demo.TestCases.DDD@1737834]" started-at="2024-01-18T01:19:59 PST" name="After_TC_Failure" finished-at="2024-01-18T01:19:59 PST" duration-ms="249" status="PASS">
          <params>
            <param index="0">
              <value>
                <![CDATA[public void com.kavi.demo.TestCases.DDD.DDDT() throws java.lang.Exception]]>
              </value>
            </param>
            <param index="1">
              <value>
                <![CDATA[[TestResult name=DDDT status=FAILURE method=DDD.DDDT()[pri:0, instance:com.kavi.demo.TestCases.DDD@1737834] output={null}]]]>
              </value>
            </param>
          </params>
          <reporter-output>
          </reporter-output>
        </test-method> <!-- After_TC_Failure -->
        <test-method is-config="true" signature="initializeReport(org.testng.ITestContext)[pri:0, instance:com.kavi.demo.TestCases.DDD@1737834]" started-at="2024-01-18T01:19:59 PST" name="initializeReport" finished-at="2024-01-18T01:19:59 PST" duration-ms="1" status="PASS">
          <params>
            <param index="0">
              <value>
                <![CDATA[org.testng.TestRunner@56082f59]]>
              </value>
            </param>
          </params>
          <reporter-output>
          </reporter-output>
        </test-method> <!-- initializeReport -->
        <test-method signature="DDDT()[pri:0, instance:com.kavi.demo.TestCases.DDD@1737834]" started-at="2024-01-18T01:19:59 PST" name="DDDT" finished-at="2024-01-18T01:20:10 PST" duration-ms="11183" status="FAIL">
          <exception class="java.lang.AssertionError">
            <message>
              <![CDATA[expected [https://qpot.omfysgroup.com/dashboard] but found [https://qpot.omfysgroup.com/]]]>
            </message>
            <full-stacktrace>
              <![CDATA[java.lang.AssertionError: expected [https://qpot.omfysgroup.com/dashboard] but found [https://qpot.omfysgroup.com/]
at org.testng.Assert.fail(Assert.java:110)
at org.testng.Assert.failNotEquals(Assert.java:1577)
at org.testng.Assert.assertEqualsImpl(Assert.java:149)
at org.testng.Assert.assertEquals(Assert.java:131)
at org.testng.Assert.assertEquals(Assert.java:655)
at org.testng.Assert.assertEquals(Assert.java:665)
at com.kavi.demo.TestCases.DDD.DDDT(DDD.java:158)
at java.base/jdk.internal.reflect.DirectMethodHandleAccessor.invoke(DirectMethodHandleAccessor.java:104)
at java.base/java.lang.reflect.Method.invoke(Method.java:578)
at org.testng.internal.invokers.MethodInvocationHelper.invokeMethod(MethodInvocationHelper.java:139)
at org.testng.internal.invokers.TestInvoker.invokeMethod(TestInvoker.java:677)
at org.testng.internal.invokers.TestInvoker.invokeTestMethod(TestInvoker.java:221)
at org.testng.internal.invokers.MethodRunner.runInSequence(MethodRunner.java:50)
at org.testng.internal.invokers.TestInvoker$MethodInvocationAgent.invoke(TestInvoker.java:969)
at org.testng.internal.invokers.TestInvoker.invokeTestMethods(TestInvoker.java:194)
at org.testng.internal.invokers.TestMethodWorker.invokeTestMethods(TestMethodWorker.java:148)
at org.testng.internal.invokers.TestMethodWorker.run(TestMethodWorker.java:128)
at java.base/java.util.ArrayList.forEach(ArrayList.java:1511)
at org.testng.TestRunner.privateRun(TestRunner.java:829)
at org.testng.TestRunner.run(TestRunner.java:602)
at org.testng.SuiteRunner.runTest(SuiteRunner.java:437)
at org.testng.SuiteRunner.runSequentially(SuiteRunner.java:431)
at org.testng.SuiteRunner.privateRun(SuiteRunner.java:391)
at org.testng.SuiteRunner.run(SuiteRunner.java:330)
at org.testng.SuiteRunnerWorker.runSuite(SuiteRunnerWorker.java:52)
at org.testng.SuiteRunnerWorker.run(SuiteRunnerWorker.java:95)
at org.testng.TestNG.runSuitesSequentially(TestNG.java:1256)
at org.testng.TestNG.runSuitesLocally(TestNG.java:1176)
at org.testng.TestNG.runSuites(TestNG.java:1099)
at org.testng.TestNG.run(TestNG.java:1067)
at org.testng.remote.AbstractRemoteTestNG.run(AbstractRemoteTestNG.java:115)
at org.testng.remote.RemoteTestNG.initAndRun(RemoteTestNG.java:251)
at org.testng.remote.RemoteTestNG.main(RemoteTestNG.java:77)
]]>
            </full-stacktrace>
          </exception> <!-- java.lang.AssertionError -->
          <reporter-output>
          </reporter-output>
        </test-method> <!-- DDDT -->
        <test-method is-config="true" signature="After_TC_Failure(java.lang.reflect.Method,org.testng.ITestResult)[pri:0, instance:com.kavi.demo.TestCases.DDD@1737834]" started-at="2024-01-18T01:20:10 PST" name="After_TC_Failure" finished-at="2024-01-18T01:20:10 PST" duration-ms="263" status="PASS">
          <params>
            <param index="0">
              <value>
                <![CDATA[public void com.kavi.demo.TestCases.DDD.DDDT() throws java.lang.Exception]]>
              </value>
            </param>
            <param index="1">
              <value>
                <![CDATA[[TestResult name=DDDT status=FAILURE method=DDD.DDDT()[pri:0, instance:com.kavi.demo.TestCases.DDD@1737834] output={null}]]]>
              </value>
            </param>
          </params>
          <reporter-output>
          </reporter-output>
        </test-method> <!-- After_TC_Failure -->
        <test-method is-config="true" signature="Demolish()[pri:0, instance:com.kavi.demo.TestCases.DDD@1737834]" started-at="2024-01-18T01:20:10 PST" name="Demolish" finished-at="2024-01-18T01:20:15 PST" duration-ms="4068" status="PASS">
          <reporter-output>
          </reporter-output>
        </test-method> <!-- Demolish -->
        <test-method is-config="true" signature="generateExtentReprts()[pri:0, instance:com.kavi.demo.TestCases.DDD@1737834]" started-at="2024-01-18T01:20:15 PST" name="generateExtentReprts" finished-at="2024-01-18T01:20:18 PST" duration-ms="2954" status="PASS">
          <reporter-output>
          </reporter-output>
        </test-method> <!-- generateExtentReprts -->
      </class> <!-- com.kavi.demo.TestCases.DDD -->
    </test> <!-- Test -->
  </suite> <!-- Suite -->
</testng-results>
